# 27 패닉과 복구 사용하기

##### 패닉

프로그램이 잘못되어 에러가 발생한 뒤 종료되는 상황

```go
a := [...]int{1,2}

for i :=0 0; i < 3; i ++ {
    fmt.Println(a[i])
}

//
panic : index out of range
```

panic 함수를 사용하면, 사용자가 직접 에러를 발생시킬 수 있다.

##### recover() 

패닉이 발생했을 경우, 프로그램이 바로 종료되지 않고 예외 처리를 할 수 있으며, try-catch 구문과 비슷하게 동작한다. 

```go
func f() {
    defer func() {
        s := recover()
        
        fmt.println(s)
    }
    
    panic("Error !!!")
}

func main() {
    f()
    
    fmt.Println("Hello,World")
}
```

panic 함수에서 설정한 에러를 받아온다. 

따라서, recover 함수는 지연 호출 함수로 사용해야한다. 그렇지 않으면 프로그램이 바로 종료된다. 



실제 런타임 에러 상황에서도  `recover()` 사용 하면 프로그램이 계속 종료되지 않고 실행한다.

```go
func s() {
	a := [...]int{1,2}
    
    for i :=0 0; i < 3; i ++ {
        fmt.Println(a[i])
    }
}

func main() {
    f()
    fmt.Println("Hello, world!") // 에러 낫지만, recover 가 복구해서 아래 값이 실행된다.
}

```

